Workbook

Sheet Leeme
A1: Codificación de obligaciones de registro en el alta bancaria digital
A2: María Fernanda Sánchez Villa · Ensayo para el Premio Federico Prades 2026 · Base de datos del componente A de la metodología
A4: Qué contiene
A5: Cada fila de "Codificacion" codifica una obligación concreta relacionada con el alta de un cliente persona física. No todas las obligaciones crean por sí mismas un registro del estado: esa diferencia se explicita en "Auditoria_ECG0".
A6: Total: 176 obligaciones de 17 instrumentos codificados, agrupados en 9 familias normativas. Se añaden actos de apoyo para verificar modificaciones y fechas de aplicación.
A8: Hojas
A9: Libro_codigos: campos, definiciones y valores cerrados admitidos, y la taxonomía de estados E0 a E9.
A10: Codificacion: base principal. Las columnas S a AC marcan con 1 los estados a los que se refiere cada obligación (calculadas por fórmula).
A11: Resumen: recuentos por familia, tipo, finalidad y cobertura de solicitudes no culminadas, y la matriz de solapamiento por dato.
A12: Mapa_visibilidad: recuento descriptivo original por estados y familias. "Mapa_ECG0" ofrece la lectura cualitativa E/C/G/0 más conservadora.
A13: Fiabilidad: muestra aleatoria del 20 % para la recodificación ciega y el cálculo del porcentaje de acuerdo.
A14: Fuentes: instrumentos codificados, enlaces y situación temporal. "Auditoria_ECG0" añade trigger, aplicabilidad al corte y límites de reutilización.
... A35: Mapa_ensayo: recuento por estados y motivos de la taxonomía del ensayo (S0-S6, R01-R11). Mapa_ECG0_ensayo: lectura E/C/G/0 en esos mismos códigos (Figura 5 del ensayo).

Sheet Libro_codigos
A1: Campo | B1: Definición | C1: Valores admitidos | F1: nivel | G1: tipo | H1: dato | I1: finalidad | J1: destinatario | K1: ambito | L1: cubre_no_culminado | M1: confianza
A2: id | B2: Identificador único: prefijo de norma y número correlativo | C2: PAD-, ES-PAD-, ES-TR-, AMLR-, ES-AML-, EBA-RO-, EBA-DR-, GDPR-, AIA-, DORA-, EIDAS-, ES-EAA- | F2: UE_reglamento | G2: Registrar | H2: Identidad | I2: Diligencia_debida_AML | J2: Interesado | K2: Todas_entidades_obligadas | L2: Si | M2: Alta
A3: familia | B3: Agrupación normativa usada en el mapa de visibilidad | C3: Cuenta básica, AML, Directrices EBA, RGPD, AI Act, DORA, eIDAS 2, Accesibilidad, Atención al cliente ES | F3: UE_directiva | G3: Conservar | H3: Documento_identidad | I3: Prevencion_fraude | J3: Autoridad_AML | K3: Cuenta_pago_basica | L3: Parcial | M3: Media
A4: norma | B4: Instrumento normativo (nombre corto) | C4: Texto libre | F4: ES_ley | G4: Comunicar_autoridad | H4: Resultado_verificacion | I4: Transparencia_consumidor | J4: Banco_de_Espana | K4: Sistemas_IA_alto_riesgo | L4: No
A5: articulo | B5: Artículo y apartado exactos (o párrafo, en directrices EBA) | C5: Texto libre | F5: ES_reglamento | G5: Informar_interesado | H5: Motivo_decision | I5: Acceso_inclusion | J5: Autoridad_proteccion_datos | K5: Responsable_tratamiento
A6: nivel | B6: Rango del instrumento | C6: UE_reglamento, UE_directiva, ES_ley, ES_reglamento, Soft_law_EBA | F6: Soft_law_EBA | G6: Motivar | H6: Logs_sistema | I6: Proteccion_datos | J6: Autoridad_vigilancia_IA | K6: Entidades_financieras_DORA
A7: vigencia | B7: Situación temporal de aplicación o transición | C7: Vigente | Aplicable_desde_AAAA-MM-DD | En_vigor_AAAA-MM-DD_adaptacion_hasta_AAAA-MM-DD | G7: Evaluar_riesgo | H7: Informacion_tratamiento | I7: Trazabilidad_IA | J7: Uso_interno
A8: tipo | B8: Qué exige la obligación | C8: Registrar, Conservar, Comunicar_autoridad, Informar_interesado, Motivar, Evaluar_riesgo, Supervision_humana, Notificar_incidente, Abstenerse | G8: Supervision_humana | H8: Evaluacion_riesgo | I8: Resiliencia_operativa | J8: Varios
A9: estado | B9: Estados de la taxonomía a los que se refiere (varios, orden ascendente, separados por "; ") | C9: E0 a E9, TR (ver tabla inferior) | G9: Notificar_incidente | H9: Intervencion_humana | I9: Reclamaciones
A10: dato | B10: Categoría de dato o evidencia exigida | C10: Identidad, Documento_identidad, Resultado_verificacion, Motivo_decision, Logs_sistema, Informacion_tratamiento, Evaluacion_riesgo, Intervencion_humana, Incidente_TIC, Proveedor_tercero, Expediente_completo | G10: Abstenerse | H10: Incidente_TIC
A11: finalidad | B11: Para qué se exige | C11: Diligencia_debida_AML, Prevencion_fraude, Transparencia_consumidor, Acceso_inclusion, Proteccion_datos, Trazabilidad_IA, Resiliencia_operativa, Reclamaciones | H11: Proveedor_tercero
A12: plazo | B12: Plazo de conservación o de actuación, literal breve | C12: "5 años", "10 años", "Mínimo 6 meses", "No especificado" u otro literal | H12: Expediente_completo
A13: destinatario | B13: Quién recibe o puede recibir la evidencia | C13: Interesado, Autoridad_AML, Banco_de_Espana, Autoridad_proteccion_datos, Autoridad_vigilancia_IA, Uso_interno, Varios
A14: ambito | B14: A quién se aplica | C14: Todas_entidades_obligadas, Cuenta_pago_basica, Sistemas_IA_alto_riesgo, Responsable_tratamiento, Entidades_financieras_DORA
A15: cubre_no_culminado | B15: ¿Alcanza, aunque sea en parte, a solicitudes que no terminan en alta? | C15: Si, Parcial, No
A16: cita | B16: Cita literal breve (máx. 35 palabras) del texto oficial en español | C16: Texto literal; "(...)" indica recorte
A17: url | B17: Enlace al texto oficial | C17: EUR-Lex, BOE, EBA
A18: confianza | B18: Alta: verificado en el texto oficial. Media: pendiente de verificar | C18: Alta, Media
A19: notas | B19: Aclaraciones de codificación | C19: Texto libre
A21: Taxonomía de estados
A22: Código | B22: Estado | C22: ¿Culmina?
A23: E0 | B23: Iniciado | C23: En curso
A24: E1 | B24: Abandono temprano | C24: No
A25: E2 | B25: Fallo técnico | C25: No
A26: E3 | B26: Documento no admitido | C26: No
A27: E4 | B27: Diligencia debida incompleta | C27: No
A28: E5 | B28: En revisión manual | C28: En curso
A29: E6 | B29: Revisión sin resolución | C29: No
A30: E7 | B30: Desistimiento tras requerimiento | C30: No
A31: E8 | B31: Denegación formal | C31: No
A32: E9 | B32: Alta completada | C32: Sí
A33: TR | B33: Transversal | C33: No aplica
A35: Visibilidad E/C/G/0
A36: Código | B36: Definición | C36: Regla de uso
A37: E | B37: Evidencia directa | C37: La obligación exige documentar, registrar, conservar, motivar o comunicar de forma verificable el evento/estado codificado.
A38: C | B38: Cobertura condicional o indirecta | C38: El estado solo queda visible si se activa un supuesto adicional (p. ej., sospecha AML, incidente TIC, reclamación o IA de alto riesgo).
A39: G | B39: Gobernanza del dato/proceso | C39: La norma gobierna datos, finalidad, minimización, seguridad o proceso asociado, pero no exige registrar ese estado de onboarding como tal.
A40: 0 | B40: No identificado | C40: En las fuentes revisadas no se identifica una obligación específica que haga visible ese estado.
A41: Nota | B41: No equivale a duplicidad | C41: Solapamiento semántico o probatorio no demuestra duplicidad operativa ni duplicidad regulatoria.

Sheet Codificacion
A1: id | B1: familia | C1: norma | D1: articulo | E1: nivel | F1: vigencia | G1: tipo | H1: estado | I1: dato | J1: finalidad | K1: plazo | L1: destinatario | M1: ambito | N1: cubre_no_culminado | O1: cita | P1: url | Q1: confianza | R1: notas | S1: E0 | T1: E1 | U1: E2 | V1: E3 | W1: E4 | X1: E5 | Y1: E6 | Z1: E7 | AA1: E8 | AB1: E9 | AC1: TR | AD1: codigos_ensayo | AE1: S0 | AF1: R01 | AG1: R02/R03 | AH1: R04 | AI1: R05 | AJ1: S3/R06 | AK1: R07 | AL1: R09 | AM1: R10 | AN1: S5 | AO1: S6 | AP1: TR
A2: PAD-01 | B2: Cuenta básica | C2: Directiva 2014/92/UE (PAD) | D2: art. 15 | E2: UE_directiva | F2: Vigente | G2: Abstenerse | H2: TR | I2: Identidad | J2: Acceso_inclusion | K2: No especificado | L2: Interesado | M2: Cuenta_pago_basica | N2: Si | O2: los proveedores de servicios de pago no discriminen a los consumidores que residan legalmente en la Unión por razón de nacionalidad o lugar de residencia (...) cuando soliciten o accedan a una cuenta de pago | P2: https://eur-lex.europa.eu/legal-content/ES/TXT/HTML/?uri=CELEX:32014L0092 | Q2: Alta | R2: Se aplica a cualquier cuenta de pago, no solo CPB. Corregida la cita: el sujeto es «proveedores de servicios de pago» (no solo entidades de crédito); incluye cualquier otra razón del art. 21 de la Carta. Verificado en el texto ES de EUR-Lex. Obligación dirigida a los Estados miembros ('velarán por que'), exigible a las entidades a través de la transposición (RDL 19/2017). | S2: =IF(ISNUMBER(SEARCH("E0",$H2)),1,0) -> 0 | T2: =IF(ISNUMBER(SEARCH("E1",$H2)),1,0) -> 0 | U2: =IF(ISNUMBER(SEARCH("E2",$H2)),1,0) -> 0 | V2: =IF(ISNUMBER(SEARCH("E3",$H2)),1,0) -> 0 | W2: =IF(ISNUMBER(SEARCH("E4",$H2)),1,0) -> 0 | X2: =IF(ISNUMBER(SEARCH("E5",$H2)),1,0) -> 0 | Y2: =IF(ISNUMBER(SEARCH("E6",$H2)),1,0) -> 0 | Z2: =IF(ISNUMBER(SEARCH("E7",$H2)),1,0) -> 0 | AA2: =IF(ISNUMBER(SEARCH("E8",$H2)),1,0) -> 0 | AB2: =IF(ISNUMBER(SEARCH("E9",$H2)),1,0) -> 0 | AC2: =IF(ISNUMBER(SEARCH("TR",$H2)),1,0) -> 1 | AD2: TR | AE2: =IF(ISNUMBER(SEARCH("S0",$AD2)),1,0) -> 0 | AF2: =IF(ISNUMBER(SEARCH("R01",$AD2)),1,0) -> 0 | AG2: =IF(ISNUMBER(SEARCH("R02R03",$AD2)),1,0) -> 0 | AH2: =IF(ISNUMBER(SEARCH("R04",$AD2)),1,0) -> 0 | AI2: =IF(ISNUMBER(SEARCH("R05",$AD2)),1,0) -> 0 | AJ2: =IF(ISNUMBER(SEARCH("S3R06",$AD2)),1,0) -> 0 | AK2: =IF(ISNUMBER(SEARCH("R07",$AD2)),1,0) -> 0 | AL2: =IF(ISNUMBER(SEARCH("R09",$AD2)),1,0) -> 0 | AM2: =IF(ISNUMBER(SEARCH("R10",$AD2)),1,0) -> 0 | AN2: =IF(ISNUMBER(SEARCH("S5",$AD2)),1,0) -> 0 | AO2: =IF(ISNUMBER(SEARCH("S6",$AD2)),1,0) -> 0 | AP2: =IF(ISNUMBER(SEARCH("TR",$AD2)),1,0) -> 1
A3: PAD-02 | B3: Cuenta básica | C3: Directiva 2014/92/UE (PAD) | D3: art. 16.3 | E3: UE_directiva | F3: Vigente | G3: Informar_interesado | H3: E8; E9 | I3: Motivo_decision | J3: Acceso_inclusion | K3: 10 días hábiles desde la recepción de una solicitud completa | L3: Interesado | M3: Cuenta_pago_basica | N3: Si | O3: rechacen las solicitudes de acceso (...) sin demora injustificada y, a más tardar en un plazo de diez días hábiles a partir de la recepción de una solicitud completa. | P3: https://eur-lex.europa.eu/legal-content/ES/TXT/HTML/?uri=CELEX:32014L0092 | Q3: Alta | R3: Obligación de resolver (abrir o denegar) en plazo; el tipo es aproximado. El RDL 19/2017 solo transpone expresamente el plazo para la denegación (art. 5.2). Ojo: la versión ES dice literalmente «rechacen» (la versión inglesa dice tramitar, abrir o rechazar); probable defecto de traducción, la corrección de errores 32014L0092R(01) no tiene versión ES en EUR-Lex y la R(02) no la he comprobado. Verificado en el texto ES de EUR-Lex. Obligación dirigida a los Estados miembros ('velarán por que'), exigible a las entidades a través de la transposición (RDL 19/2017). | S3: =IF(ISNUMBER(SEARCH("E0",$H3)),1,0) -> 0 | T3: =IF(ISNUMBER(SEARCH("E1",$H3)),1,0) -> 0 | U3: =IF(ISNUMBER(SEARCH("E2",$H3)),1,0) -> 0 | V3: =IF(ISNUMBER(SEARCH("E3",$H3)),1,0) -> 0 | W3: =IF(ISNUMBER(SEARCH("E4",$H3)),1,0) -> 0 | X3: =IF(ISNUMBER(SEARCH("E5",$H3)),1,0) -> 0 | Y3: =IF(ISNUMBER(SEARCH("E6",$H3)),1,0) -> 0 | Z3: =IF(ISNUMBER(SEARCH("E7",$H3)),1,0) -> 0 | AA3: =IF(ISNUMBER(SEARCH("E8",$H3)),1,0) -> 1 | AB3: =IF(ISNUMBER(SEARCH("E9",$H3)),1,0) -> 1 | AC3: =IF(ISNUMBER(SEARCH("TR",$H3)),1,0) -> 0 | AD3: S5; S6 | AE3: =IF(ISNUMBER(SEARCH("S0",$AD3)),1,0) -> 0 | AF3: =IF(ISNUMBER(SEARCH("R01",$AD3)),1,0) -> 0 | AG3: =IF(ISNUMBER(SEARCH("R02R03",$AD3)),1,0) -> 0 | AH3: =IF(ISNUMBER(SEARCH("R04",$AD3)),1,0) -> 0 | AI3: =IF(ISNUMBER(SEARCH("R05",$AD3)),1,0) -> 0 | AJ3: =IF(ISNUMBER(SEARCH("S3R06",$AD3)),1,0) -> 0 | AK3: =IF(ISNUMBER(SEARCH("R07",$AD3)),1,0) -> 0 | AL3: =IF(ISNUMBER(SEARCH("R09",$AD3)),1,0) -> 0 | AM3: =IF(ISNUMBER(SEARCH("R10",$AD3)),1,0) -> 0 | AN3: =IF(ISNUMBER(SEARCH("S5",$AD3)),1,0) -> 1 | AO3: =IF(ISNUMBER(SEARCH("S6",$AD3)),1,0) -> 1 | AP3: =IF(ISNUMBER(SEARCH("TR",$AD3)),1,0) -> 0
A4: PAD-03 | B4: Cuenta básica | C4: Directiva 2014/92/UE (PAD) | D4: art. 16.4 | E4: UE_directiva | F4: Vigente | G4: Abstenerse | H4: E4; E8 | I4: Resultado_verificacion | J4: Diligencia_debida_AML | K4: No especificado | L4: Interesado | M4: Cuenta_pago_basica | N4: Si | O4: las entidades de crédito rechacen las solicitudes de acceso a cuentas de pago básicas siempre que la apertura de una de tales cuentas vulnere las disposiciones relativas a la prevención del blanqueo de capitales | P4: https://eur-lex.europa.eu/legal-content/ES/TXT/HTML/?uri=CELEX:32014L0092 | Q4: Alta | R4: Remite a la Directiva 2005/60/CE (hoy marco AMLR/AMLD). Verificado en el texto ES de EUR-Lex. Obligación dirigida a los Estados miembros ('velarán por que'), exigible a las entidades a través de la transposición (RDL 19/2017). | S4: =IF(ISNUMBER(SEARCH("E0",$H4)),1,0) -> 0 | T4: =IF(ISNUMBER(SEARCH("E1",$H4)),1,0) -> 0 | U4: =IF(ISNUMBER(SEARCH("E2",$H4)),1,0) -> 0 | V4: =IF(ISNUMBER(SEARCH("E3",$H4)),1,0) -> 0 | W4: =IF(ISNUMBER(SEARCH("E4",$H4)),1,0) -> 1 | X4: =IF(ISNUMBER(SEARCH("E5",$H4)),1,0) -> 0 | Y4: =IF(ISNUMBER(SEARCH("E6",$H4)),1,0) -> 0 | Z4: =IF(ISNUMBER(SEARCH("E7",$H4)),1,0) -> 0 | AA4: =IF(ISNUMBER(SEARCH("E8",$H4)),1,0) -> 1 | AB4: =IF(ISNUMBER(SEARCH("E9",$H4)),1,0) -> 0 | AC4: =IF(ISNUMBER(SEARCH("TR",$H4)),1,0) -> 0 | AD4: R05; R07; S5 | AE4: =IF(ISNUMBER(SEARCH("S0",$AD4)),1,0) -> 0 | AF4: =IF(ISNUMBER(SEARCH("R01",$AD4)),1,0) -> 0 | AG4: =IF(ISNUMBER(SEARCH("R02R03",$AD4)),1,0) -> 0 | AH4: =IF(ISNUMBER(SEARCH("R04",$AD4)),1,0) -> 0 | AI4: =IF(ISNUMBER(SEARCH("R05",$AD4)),1,0) -> 1 | AJ4: =IF(ISNUMBER(SEARCH("S3R06",$AD4)),1,0) -> 0 | AK4: =IF(ISNUMBER(SEARCH("R07",$AD4)),1,0) -> 1 | AL4: =IF(ISNUMBER(SEARCH("R09",$AD4)),1,0) -> 0 | AM4: =IF(ISNUMBER(SEARCH("R10",$AD4)),1,0) -> 0 | AN4: =IF(ISNUMBER(SEARCH("S5",$AD4)),1,0) -> 1 | AO4: =IF(ISNUMBER(SEARCH("S6",$AD4)),1,0) -> 0 | AP4: =IF(ISNUMBER(SEARCH("TR",$AD4)),1,0) -> 0
A5: PAD-04 | B5: Cuenta básica | C5: Directiva 2014/92/UE (PAD) | D5: art. 16.7 | E5: UE_directiva | F5: Vigente | G5: Informar_interesado | H5: E8 | I5: Motivo_decision | J5: Acceso_inclusion | K5: Inmediatamente tras la decisión | L5: Interesado | M5: Cuenta_pago_basica | N5: Si | O5: la entidad de crédito, una vez tomada su decisión, comunique inmediatamente al consumidor la denegación y los motivos específicos de tal denegación, por escrito y de forma gratuita | P5: https://eur-lex.europa.eu/legal-content/ES/TXT/HTML/?uri=CELEX:32014L0092 | Q5: Alta | R5: Excepción: cuando la comunicación sea contraria a la seguridad nacional, el orden público o la normativa AML. Aplica a denegaciones de los apdos. 4, 5 y 6. Cita corregida al texto literal. Verificado en el texto ES de EUR-Lex. Obligación dirigida a los Estados miembros ('velarán por que'), exigible a las entidades a través de la transposición (RDL 19/2017). | S5: =IF(ISNUMBER(SEARCH("E0",$H5)),1,0) -> 0 | T5: =IF(ISNUMBER(SEARCH("E1",$H5)),1,0) -> 0 | U5: =IF(ISNUMBER(SEARCH("E2",$H5)),1,0) -> 0 | V5: =IF(ISNUMBER(SEARCH("E3",$H5)),1,0) -> 0 | W5: =IF(ISNUMBER(SEARCH("E4",$H5)),1,0) -> 0 | X5: =IF(ISNUMBER(SEARCH("E5",$H5)),1,0) -> 0 | Y5: =IF(ISNUMBER(SEARCH("E6",$H5)),1,0) -> 0 | Z5: =IF(ISNUMBER(SEARCH("E7",$H5)),1,0) -> 0 | AA5: =IF(ISNUMBER(SEARCH("E8",$H5)),1,0) -> 1 | AB5: =IF(ISNUMBER(SEARCH("E9",$H5)),1,0) -> 0 | AC5: =IF(ISNUMBER(SEARCH("TR",$H5)),1,0) -> 0 | AD5: S5 | AE5: =IF(ISNUMBER(SEARCH("S0",$AD5)),1,0) -> 0 | AF5: =IF(ISNUMBER(SEARCH("R01",$AD5)),1,0) -> 0 | AG5: =IF(ISNUMBER(SEARCH("R02R03",$AD5)),1,0) -> 0 | AH5: =IF(ISNUMBER(SEARCH("R04",$AD5)),1,0) -> 0 | AI5: =IF(ISNUMBER(SEARCH("R05",$AD5)),1,0) -> 0 | AJ5: =IF(ISNUMBER(SEARCH("S3R06",$AD5)),1,0) -> 0 | AK5: =IF(ISNUMBER(SEARCH("R07",$AD5)),1,0) -> 0 | AL5: =IF(ISNUMBER(SEARCH("R09",$AD5)),1,0) -> 0 | AM5: =IF(ISNUMBER(SEARCH("R10",$AD5)),1,0) -> 0 | AN5: =IF(ISNUMBER(SEARCH("S5",$AD5)),1,0) -> 1 | AO5: =IF(ISNUMBER(SEARCH("S6",$AD5)),1,0) -> 0 | AP5: =IF(ISNUMBER(SEARCH("TR",$AD5)),1,0) -> 0
A6: PAD-05 | B6: Cuenta básica | C6: Directiva 2014/92/UE (PAD) | D6: art. 16.7 | E6: UE_directiva | F6: Vigente | G6: Motivar | H6: E8 | I6: Motivo_decision | J6: Transparencia_consumidor | K6: Inmediatamente tras la decisión | L6: Interesado | M6: Cuenta_pago_basica | N6: Si | O6: comunique inmediatamente al consumidor la denegación y los motivos específicos de tal denegación, por escrito y de forma gratuita, a menos que ello vaya en detrimento de los intereses de seguridad nacional | P6: https://eur-lex.europa.eu/legal-content/ES/TXT/HTML/?uri=CELEX:32014L0092 | Q6: Alta | R6: Misma excepción AML/seguridad nacional/orden público que PAD-04. Cita corregida al texto literal. Verificado en el texto ES de EUR-Lex. Obligación dirigida a los Estados miembros ('velarán por que'), exigible a las entidades a través de la transposición (RDL 19/2017). | S6: =IF(ISNUMBER(SEARCH("E0",$H6)),1,0) -> 0 | T6: =IF(ISNUMBER(SEARCH("E1",$H6)),1,0) -> 0 | U6: =IF(ISNUMBER(SEARCH("E2",$H6)),1,0) -> 0 | V6: =IF(ISNUMBER(SEARCH("E3",$H6)),1,0) -> 0 | W6: =IF(ISNUMBER(SEARCH("E4",$H6)),1,0) -> 0 | X6: =IF(ISNUMBER(SEARCH("E5",$H6)),1,0) -> 0 | Y6: =IF(ISNUMBER(SEARCH("E6",$H6)),1,0) -> 0 | Z6: =IF(ISNUMBER(SEARCH("E7",$H6)),1,0) -> 0 | AA6: =IF(ISNUMBER(SEARCH("E8",$H6)),1,0) -> 1 | AB6: =IF(ISNUMBER(SEARCH("E9",$H6)),1,0) -> 0 | AC6: =IF(ISNUMBER(SEARCH("TR",$H6)),1,0) -> 0 | AD6: S5 | AE6: =IF(ISNUMBER(SEARCH("S0",$AD6)),1,0) -> 0 | AF6: =IF(ISNUMBER(SEARCH("R01",$AD6)),1,0) -> 0 | AG6: =IF(ISNUMBER(SEARCH("R02R03",$AD6)),1,0) -> 0 | AH6: =IF(ISNUMBER(SEARCH("R04",$AD6)),1,0) -> 0 | AI6: =IF(ISNUMBER(SEARCH("R05",$AD6)),1,0) -> 0 | AJ6: =IF(ISNUMBER(SEARCH("S3R06",$AD6)),1,0) -> 0 | AK6: =IF(ISNUMBER(SEARCH("R07",$AD6)),1,0) -> 0 | AL6: =IF(ISNUMBER(SEARCH("R09",$AD6)),1,0) -> 0 | AM6: =IF(ISNUMBER(SEARCH("R10",$AD6)),1,0) -> 0 | AN6: =IF(ISNUMBER(SEARCH("S5",$AD6)),1,0) -> 1 | AO6: =IF(ISNUMBER(SEARCH("S6",$AD6)),1,0) -> 0 | AP6: =IF(ISNUMBER(SEARCH("TR",$AD6)),1,0) -> 0
A7: PAD-06 | B7: Cuenta básica | C7: Directiva 2014/92/UE (PAD) | D7: art. 16.7 | E7: UE_directiva | F7: Vigente | G7: Informar_interesado | H7: E8 | I7: Motivo_decision | J7: Reclamaciones | K7: No especificado | L7: Interesado | M7: Cuenta_pago_basica | N7: Si | O7: la entidad de crédito deberá informar al consumidor del procedimiento que ha de seguir para presentar una reclamación contra la denegación y de su derecho a dirigirse a la autoridad competente correspondiente | P7: https://eur-lex.europa.eu/legal-content/ES/TXT/HTML/?uri=CELEX:32014L0092 | Q7: Alta | R7: Incluye facilitar los datos de contacto pertinentes. Cita corregida al texto literal. Verificado en el texto ES de EUR-Lex. Obligación dirigida a los Estados miembros ('velarán por que'), exigible a las entidades a través de la transposición (RDL 19/2017). | S7: =IF(ISNUMBER(SEARCH("E0",$H7)),1,0) -> 0 | T7: =IF(ISNUMBER(SEARCH("E1",$H7)),1,0) -> 0 | U7: =IF(ISNUMBER(SEARCH("E2",$H7)),1,0) -> 0 | V7: =IF(ISNUMBER(SEARCH("E3",$H7)),1,0) -> 0 | W7: =IF(ISNUMBER(SEARCH("E4",$H7)),1,0) -> 0 | X7: =IF(ISNUMBER(SEARCH("E5",$H7)),1,0) -> 0 | Y7: =IF(ISNUMBER(SEARCH("E6",$H7)),1,0) -> 0 | Z7: =IF(ISNUMBER(SEARCH("E7",$H7)),1,0) -> 0 | AA7: =IF(ISNUMBER(SEARCH("E8",$H7)),1,0) -> 1 | AB7: =IF(ISNUMBER(SEARCH("E9",$H7)),1,0) -> 0 | AC7: =IF(ISNUMBER(SEARCH("TR",$H7)),1,0) -> 0 | AD7: S5 | AE7: =IF(ISNUMBER(SEARCH("S0",$AD7)),1,0) -> 0 | AF7: =IF(ISNUMBER(SEARCH("R01",$AD7)),1,0) -> 0 | AG7: =IF(ISNUMBER(SEARCH("R02R03",$AD7)),1,0) -> 0 | AH7: =IF(ISNUMBER(SEARCH("R04",$AD7)),1,0) -> 0 | AI7: =IF(ISNUMBER(SEARCH("R05",$AD7)),1,0) -> 0 | AJ7: =IF(ISNUMBER(SEARCH("S3R06",$AD7)),1,0) -> 0 | AK7: =IF(ISNUMBER(SEARCH("R07",$AD7)),1,0) -> 0 | AL7: =IF(ISNUMBER(SEARCH("R09",$AD7)),1,0) -> 0 | AM7: =IF(ISNUMBER(SEARCH("R10",$AD7)),1,0) -> 0 | AN7: =IF(ISNUMBER(SEARCH("S5",$AD7)),1,0) -> 1 | AO7: =IF(ISNUMBER(SEARCH("S6",$AD7)),1,0) -> 0 | AP7: =IF(ISNUMBER(SEARCH("TR",$AD7)),1,0) -> 0
A8: PAD-07 | B8: Cuenta básica | C8: Directiva 2014/92/UE (PAD) | D8: art. 16.8 | E8: UE_directiva | F8: Vigente | G8: Comunicar_autoridad | H8: E4; E8 | I8: Expediente_completo | J8: Diligencia_debida_AML | K8: No especificado | L8: Autoridad_AML | M8: Cuenta_pago_basica | N8: Si | O8: en los casos a que se refiere el apartado 4, la entidad de crédito adopte medidas apropiadas con arreglo al capítulo III de la Directiva 2005/60/CE. | P8: https://eur-lex.europa.eu/legal-content/ES/TXT/HTML/?uri=CELEX:32014L0092 | Q8: Alta | R8: El capítulo III de la Directiva 2005/60/CE regula las obligaciones de comunicación (operaciones sospechosas); codificado como Comunicar_autoridad por esa remisión. Cita corregida al texto literal. Verificado en el texto ES de EUR-Lex. Obligación dirigida a los Estados miembros ('velarán por que'), exigible a las entidades a través de la transposición (RDL 19/2017). | S8: =IF(ISNUMBER(SEARCH("E0",$H8)),1,0) -> 0 | T8: =IF(ISNUMBER(SEARCH("E1",$H8)),1,0) -> 0 | U8: =IF(ISNUMBER(SEARCH("E2",$H8)),1,0) -> 0 | V8: =IF(ISNUMBER(SEARCH("E3",$H8)),1,0) -> 0 | W8: =IF(ISNUMBER(SEARCH("E4",$H8)),1,0) -> 1 | X8: =IF(ISNUMBER(SEARCH("E5",$H8)),1,0) -> 0 | Y8: =IF(ISNUMBER(SEARCH("E6",$H8)),1,0) -> 0 | Z8: =IF(ISNUMBER(SEARCH("E7",$H8)),1,0) -> 0 | AA8: =IF(ISNUMBER(SEARCH("E8",$H8)),1,0) -> 1 | AB8: =IF(ISNUMBER(SEARCH("E9",$H8)),1,0) -> 0 | AC8: =IF(ISNUMBER(SEARCH("TR",$H8)),1,0) -> 0 | AD8: R05; S5 | AE8: =IF(ISNUMBER(SEARCH("S0",$AD8)),1,0) -> 0 | AF8: =IF(ISNUMBER(SEARCH("R01",$AD8)),1,0) -> 0 | AG8: =IF(ISNUMBER(SEARCH("R02R03",$AD8)),1,0) -> 0 | AH8: =IF(ISNUMBER(SEARCH("R04",$AD8)),1,0) -> 0 | AI8: =IF(ISNUMBER(SEARCH("R05",$AD8)),1,0) -> 1 | AJ8: =IF(ISNUMBER(SEARCH("S3R06",$AD8)),1,0) -> 0 | AK8: =IF(ISNUMBER(SEARCH("R07",$AD8)),1,0) -> 0 | AL8: =IF(ISNUMBER(SEARCH("R09",$AD8)),1,0) -> 0 | AM8: =IF(ISNUMBER(SEARCH("R10",$AD8)),1,0) -> 0 | AN8: =IF(ISNUMBER(SEARCH("S5",$AD8)),1,0) -> 1 | AO8: =IF(ISNUMBER(SEARCH("S6",$AD8)),1,0) -> 0 | AP8: =IF(ISNUMBER(SEARCH("TR",$AD8)),1,0) -> 0
A9: PAD-08 | B9: Cuenta básica | C9: Directiva 2014/92/UE (PAD) | D9: art. 16.9 | E9: UE_directiva | F9: Vigente | G9: Abstenerse | H9: E0; E9 | I9: Expediente_completo | J9: Acceso_inclusion | K9: No especificado | L9: Interesado | M9: Cuenta_pago_basica | N9: Si | O9: el acceso a una cuenta de pago básica no se supedite a la adquisición de otros servicios o participaciones en el capital de la entidad de crédito, salvo si ello fuera obligatorio | P9: https://eur-lex.europa.eu/legal-content/ES/TXT/HTML/?uri=CELEX:32014L0092 | Q9: Alta | R9: Salvo que esto último se exija a toda la clientela de la entidad. Cita corregida al texto literal. Verificado en el texto ES de EUR-Lex. Obligación dirigida a los Estados miembros ('velarán por que'), exigible a las entidades a través de la transposición (RDL 19/2017). | S9: =IF(ISNUMBER(SEARCH("E0",$H9)),1,0) -> 1 | T9: =IF(ISNUMBER(SEARCH("E1",$H9)),1,0) -> 0 | U9: =IF(ISNUMBER(SEARCH("E2",$H9)),1,0) -> 0 | V9: =IF(ISNUMBER(SEARCH("E3",$H9)),1,0) -> 0 | W9: =IF(ISNUMBER(SEARCH("E4",$H9)),1,0) -> 0 | X9: =IF(ISNUMBER(SEARCH("E5",$H9)),1,0) -> 0 | Y9: =IF(ISNUMBER(SEARCH("E6",$H9)),1,0) -> 0 | Z9: =IF(ISNUMBER(SEARCH("E7",$H9)),1,0) -> 0 | AA9: =IF(ISNUMBER(SEARCH("E8",$H9)),1,0) -> 0 | AB9: =IF(ISNUMBER(SEARCH("E9",$H9)),1,0) -> 1 | AC9: =IF(ISNUMBER(SEARCH("TR",$H9)),1,0) -> 0 | AD9: S0; S6 | AE9: =IF(ISNUMBER(SEARCH("S0",$AD9)),1,0) -> 1 | AF9: =IF(ISNUMBER(SEARCH("R01",$AD9)),1,0) -> 0 | AG9: =IF(ISNUMBER(SEARCH("R02R03",$AD9)),1,0) -> 0 | AH9: =IF(ISNUMBER(SEARCH("R04",$AD9)),1,0) -> 0 | AI9: =IF(ISNUMBER(SEARCH("R05",$AD9)),1,0) -> 0 | AJ9: =IF(ISNUMBER(SEARCH("S3R06",$AD9)),1,0) -> 0 | AK9: =IF(ISNUMBER(SEARCH("R07",$AD9)),1,0) -> 0 | AL9: =IF(ISNUMBER(SEARCH("R09",$AD9)),1,0) -> 0 | AM9: =IF(ISNUMBER(SEARCH("R10",$AD9)),1,0) -> 0 | AN9: =IF(ISNUMBER(SEARCH("S5",$AD9)),1,0) -> 0 | AO9: =IF(ISNUMBER(SEARCH("S6",$AD9)),1,0) -> 1 | AP9: =IF(ISNUMBER(SEARCH("TR",$AD9)),1,0) -> 0
A10: PAD-09 | B10: Cuenta básica | C10: Directiva 2014/92/UE (PAD) | D10: art. 20.2 | E10: UE_directiva | F10: Vigente | G10: Informar_interesado | H10: TR | I10: Informacion_tratamiento | J10: Transparencia_consumidor | K10: No especificado | L10: Interesado | M10: Cuenta_pago_basica | N10: Si | O10: las entidades de crédito pongan gratuitamente a disposición de los consumidores información y asistencia accesibles y gratuitas sobre las características específicas de sus cuentas de pago básicas | P10: https://eur-lex.europa.eu/legal-content/ES/TXT/HTML/?uri=CELEX:32014L0092 | Q10: Alta | R10: Información sobre el producto (características, comisiones, condiciones; que no es obligatorio adquirir otros servicios); no existe categoría de dato específica. Cita corregida al texto literal. Verificado en el texto ES de EUR-Lex. Obligación dirigida a los Estados miembros ('velarán por que'), exigible a las entidades a través de la transposición (RDL 19/2017). | S10: =IF(ISNUMBER(SEARCH("E0",$H10)),1,0) -> 0 | T10: =IF(ISNUMBER(SEARCH("E1",$H10)),1,0) -> 0 | U10: =IF(ISNUMBER(SEARCH("E2",$H10)),1,0) -> 0 | V10: =IF(ISNUMBER(SEARCH("E3",$H10)),1,0) -> 0 | W10: =IF(ISNUMBER(SEARCH("E4",$H10)),1,0) -> 0 | X10: =IF(ISNUMBER(SEARCH("E5",$H10)),1,0) -> 0 | Y10: =IF(ISNUMBER(SEARCH("E6",$H10)),1,0) -> 0 | Z10: =IF(ISNUMBER(SEARCH("E7",$H10)),1,0) -> 0 | AA10: =IF(ISNUMBER(SEARCH("E8",$H10)),1,0) -> 0 | AB10: =IF(ISNUMBER(SEARCH("E9",$H10)),1,0) -> 0 | AC10: =IF(ISNUMBER(SEARCH("TR",$H10)),1,0) -> 1 | AD10: TR | AE10: =IF(ISNUMBER(SEARCH("S0",$AD10)),1,0) -> 0 | AF10: =IF(ISNUMBER(SEARCH("R01",$AD10)),1,0) -> 0 | AG10: =IF(ISNUMBER(SEARCH("R02R03",$AD10)),1,0) -> 0 | AH10: =IF(ISNUMBER(SEARCH("R04",$AD10)),1,0) -> 0 | AI10: =IF(ISNUMBER(SEARCH("R05",$AD10)),1,0) -> 0 | AJ10: =IF(ISNUMBER(SEARCH("S3R06",$AD10)),1,0) -> 0 | AK10: =IF(ISNUMBER(SEARCH("R07",$AD10)),1,0) -> 0 | AL10: =IF(ISNUMBER(SEARCH("R09",$AD10)),1,0) -> 0 | AM10: =IF(ISNUMBER(SEARCH("R10",$AD10)),1,0) -> 0 | AN10: =IF(ISNUMBER(SEARCH("S5",$AD10)),1,0) -> 0 | AO10: =IF(ISNUMBER(SEARCH("S6",$AD10)),1,0) -> 0 | AP10: =IF(ISNUMBER(SEARCH("TR",$AD10)),1,0) -> 1
A11: ES-PAD-01 | B11: Cuenta básica | C11: Real Decreto-ley 19/2017 (cuentas de pago básicas) | D11: art. 4.1.a) | E11: ES_ley | F11: Vigente | G11: Abstenerse | H11: E4; E7; E8 | I11: Resultado_verificacion | J11: Diligencia_debida_AML | K11: No especificado | L11: Interesado | M11: Cuenta_pago_basica | N11: Si | O11: Las entidades de crédito denegarán el acceso [...] cuando [...] El potencial cliente no aporte la información requerida por la entidad en función del nivel de riesgo de blanqueo de capitales | P11: https://www.boe.es/buscar/act.php?id=BOE-A-2017-13644 | Q11: Alta | R11: Remite al capítulo II de la Ley 10/2010. | S11: =IF(ISNUMBER(SEARCH("E0",$H11)),1,0) -> 0 | T11: =IF(ISNUMBER(SEARCH("E1",$H11)),1,0) -> 0 | U11: =IF(ISNUMBER(SEARCH("E2",$H11)),1,0) -> 0 | V11: =IF(ISNUMBER(SEARCH("E3",$H11)),1,0) -> 0 | W11: =IF(ISNUMBER(SEARCH("E4",$H11)),1,0) -> 1 | X11: =IF(ISNUMBER(SEARCH("E5",$H11)),1,0) -> 0 | Y11: =IF(ISNUMBER(SEARCH("E6",$H11)),1,0) -> 0 | Z11: =IF(ISNUMBER(SEARCH("E7",$H11)),1,0) -> 1 | AA11: =IF(ISNUMBER(SEARCH("E8",$H11)),1,0) -> 1 | AB11: =IF(ISNUMBER(SEARCH("E9",$H11)),1,0) -> 0 | AC11: =IF(ISNUMBER(SEARCH("TR",$H11)),1,0) -> 0 | AD11: R05; R07; R10; S5 | AE11: =IF(ISNUMBER(SEARCH("S0",$AD11)),1,0) -> 0 | AF11: =IF(ISNUMBER(SEARCH("R01",$AD11)),1,0) -> 0 | AG11: =IF(ISNUMBER(SEARCH("R02R03",$AD11)),1,0) -> 0 | AH11: =IF(ISNUMBER(SEARCH("R04",$AD11)),1,0) -> 0 | AI11: =IF(ISNUMBER(SEARCH("R05",$AD11)),1,0) -> 1 | AJ11: =IF(ISNUMBER(SEARCH("S3R06",$AD11)),1,0) -> 0 | AK11: =IF(ISNUMBER(SEARCH("R07",$AD11)),1,0) -> 1 | AL11: =IF(ISNUMBER(SEARCH("R09",$AD11)),1,0) -> 0 | AM11: =IF(ISNUMBER(SEARCH("R10",$AD11)),1,0) -> 1 | AN11: =IF(ISNUMBER(SEARCH("S5",$AD11)),1,0) -> 1 | AO11: =IF(ISNUMBER(SEARCH("S6",$AD11)),1,0) -> 0 | AP11: =IF(ISNUMBER(SEARCH("TR",$AD11)),1,0) -> 0
A12: ES-PAD-02 | B12: Cuenta básica | C12: Real Decreto-ley 19/2017 (cuentas de pago básicas) | D12: art. 4.1.b) | E12: ES_ley | F12: Vigente | G12: Abstenerse | H12: E8 | I12: Motivo_decision | J12: Acceso_inclusion | K12: No especificado | L12: Interesado | M12: Cuenta_pago_basica | N12: Si | O12: su apertura sea contraria a los intereses de la seguridad nacional o de orden público [...] en los supuestos en que así se haya acordado por el Consejo de Ministros | P12: https://www.boe.es/buscar/act.php?id=BOE-A-2017-13644 | Q12: Alta | S12: =IF(ISNUMBER(SEARCH("E0",$H12)),1,0) -> 0 | T12: =IF(ISNUMBER(SEARCH("E1",$H12)),1,0) -> 0 | U12: =IF(ISNUMBER(SEARCH("E2",$H12)),1,0) -> 0 | V12: =IF(ISNUMBER(SEARCH("E3",$H12)),1,0) -> 0 | W12: =IF(ISNUMBER(SEARCH("E4",$H12)),1,0) -> 0 | X12: =IF(ISNUMBER(SEARCH("E5",$H12)),1,0) -> 0 | Y12: =IF(ISNUMBER(SEARCH("E6",$H12)),1,0) -> 0 | Z12: =IF(ISNUMBER(SEARCH("E7",$H12)),1,0) -> 0 | AA12: =IF(ISNUMBER(SEARCH("E8",$H12)),1,0) -> 1 | AB12: =IF(ISNUMBER(SEARCH("E9",$H12)),1,0) -> 0 | AC12: =IF(ISNUMBER(SEARCH("TR",$H12)),1,0) -> 0 | AD12: S5 | AE12: =IF(ISNUMBER(SEARCH("S0",$AD12)),1,0) -> 0 | AF12: =IF(ISNUMBER(SEARCH("R01",$AD12)),1,0) -> 0 | AG12: =IF(ISNUMBER(SEARCH("R02R03",$AD12)),1,0) -> 0 | AH12: =IF(ISNUMBER(SEARCH("R04",$AD12)),1,0) -> 0 | AI12: =IF(ISNUMBER(SEARCH("R05",$AD12)),1,0) -> 0 | AJ12: =IF(ISNUMBER(SEARCH("S3R06",$AD12)),1,0) -> 0 | AK12: =IF(ISNUMBER(SEARCH("R07",$AD12)),1,0) -> 0 | AL12: =IF(ISNUMBER(SEARCH("R09",$AD12)),1,0) -> 0 | AM12: =IF(ISNUMBER(SEARCH("R10",$AD12)),1,0) -> 0 | AN12: =IF(ISNUMBER(SEARCH("S5",$AD12)),1,0) -> 1 | AO12: =IF(ISNUMBER(SEARCH("S6",$AD12)),1,0) -> 0 | AP12: =IF(ISNUMBER(SEARCH("TR",$AD12)),1,0) -> 0
A13: ES-PAD-03 | B13: Cuenta básica | C13: Real Decreto-ley 19/2017 (cuentas de pago básicas) | D13: art. 4.1.c) | E13: ES_ley | F13: Vigente | G13: Abstenerse | H13: E8 | I13: Resultado_verificacion | J13: Acceso_inclusion | K13: No especificado | L13: Interesado | M13: Cuenta_pago_basica | N13: Si | O13: el potencial cliente ya sea titular en España de una cuenta en un proveedor de servicios de pago que le permita realizar los servicios contemplados en el artículo 8.1 | P13: https://www.boe.es/buscar/act.php?id=BOE-A-2017-13644 | Q13: Alta | R13: Denegación obligatoria en España (la PAD la configura como opción). La entidad podrá verificarlo y basarse en una declaración responsable firmada por el cliente. | S13: =IF(ISNUMBER(SEARCH("E0",$H13)),1,0) -> 0 | T13: =IF(ISNUMBER(SEARCH("E1",$H13)),1,0) -> 0 | U13: =IF(ISNUMBER(SEARCH("E2",$H13)),1,0) -> 0 | V13: =IF(ISNUMBER(SEARCH("E3",$H13)),1,0) -> 0 | W13: =IF(ISNUMBER(SEARCH("E4",$H13)),1,0) -> 0 | X13: =IF(ISNUMBER(SEARCH("E5",$H13)),1,0) -> 0 | Y13: =IF(ISNUMBER(SEARCH("E6",$H13)),1,0) -> 0 | Z13: =IF(ISNUMBER(SEARCH("E7",$H13)),1,0) -> 0 | AA13: =IF(ISNUMBER(SEARCH("E8",$H13)),1,0) -> 1 | AB13: =IF(ISNUMBER(SEARCH("E9",$H13)),1,0) -> 0 | AC13: =IF(ISNUMBER(SEARCH("TR",$H13)),1,0) -> 0 | AD13: S5 | AE13: =IF(ISNUMBER(SEARCH("S0",$AD13)),1,0) -> 0 | AF13: =IF(ISNUMBER(SEARCH("R01",$AD13)),1,0) -> 0 | AG13: =IF(ISNUMBER(SEARCH("R02R03",$AD13)),1,0) -> 0 | AH13: =IF(ISNUMBER(SEARCH("R04",$AD13)),1,0) -> 0 | AI13: =IF(ISNUMBER(SEARCH("R05",$AD13)),1,0) -> 0 | AJ13: =IF(ISNUMBER(SEARCH("S3R06",$AD13)),1,0) -> 0 | AK13: =IF(ISNUMBER(SEARCH("R07",$AD13)),1,0) -> 0 | AL13: =IF(ISNUMBER(SEARCH("R09",$AD13)),1,0) -> 0 | AM13: =IF(ISNUMBER(SEARCH("R10",$AD13)),1,0) -> 0 | AN13: =IF(ISNUMBER(SEARCH("S5",$AD13)),1,0) -> 1 | AO13: =IF(ISNUMBER(SEARCH("S6",$AD13)),1,0) -> 0 | AP13: =IF(ISNUMBER(SEARCH("TR",$AD13)),1,0) -> 0
A14: ES-PAD-04 | B14: Cuenta básica | C14: Real Decreto-ley 19/2017 (cuentas de pago básicas) | D14: art. 4.1 (párrafo final) | E14: ES_ley | F14: Vigente | G14: Conservar | H14: E8 | I14: Motivo_decision | J14: Acceso_inclusion | K14: No especificado | L14: Uso_interno | M14: Cuenta_pago_basica | N14: Si | O14: La entidad conservará los documentos y el análisis realizado en el que se base esta decisión. | P14: https://www.boe.es/buscar/act.php?id=BOE-A-2017-13644 | Q14: Alta | R14: Obligación específica de conservar el expediente de la denegación; sin plazo propio en el RDL. | S14: =IF(ISNUMBER(SEARCH("E0",$H14)),1,0) -> 0 | T14: =IF(ISNUMBER(SEARCH("E1",$H14)),1,0) -> 0 | U14: =IF(ISNUMBER(SEARCH("E2",$H14)),1,0) -> 0 | V14: =IF(ISNUMBER(SEARCH("E3",$H14)),1,0) -> 0 | W14: =IF(ISNUMBER(SEARCH("E4",$H14)),1,0) -> 0 | X14: =IF(ISNUMBER(SEARCH("E5",$H14)),1,0) -> 0 | Y14: =IF(ISNUMBER(SEARCH("E6",$H14)),1,0) -> 0 | Z14: =IF(ISNUMBER(SEARCH("E7",$H14)),1,0) -> 0 | AA14: =IF(ISNUMBER(SEARCH("E8",$H14)),1,0) -> 1 | AB14: =IF(ISNUMBER(SEARCH("E9",$H14)),1,0) -> 0 | AC14: =IF(ISNUMBER(SEARCH("TR",$H14)),1,0) -> 0 | AD14: S5 | AE14: =IF(ISNUMBER(SEARCH("S0",$AD14)),1,0) -> 0 | AF14: =IF(ISNUMBER(SEARCH("R01",$AD14)),1,0) -> 0 | AG14: =IF(ISNUMBER(SEARCH("R02R03",$AD14)),1,0) -> 0 | AH14: =IF(ISNUMBER(SEARCH("R04",$AD14)),1,0) -> 0 | AI14: =IF(ISNUMBER(SEARCH("R05",$AD14)),1,0) -> 0 | AJ14: =IF(ISNUMBER(SEARCH("S3R06",$AD14)),1,0) -> 0 | AK14: =IF(ISNUMBER(SEARCH("R07",$AD14)),1,0) -> 0 | AL14: =IF(ISNUMBER(SEARCH("R09",$AD14)),1,0) -> 0 | AM14: =IF(ISNUMBER(SEARCH("R10",$AD14)),1,0) -> 0 | AN14: =IF(ISNUMBER(SEARCH("S5",$AD14)),1,0) -> 1 | AO14: =IF(ISNUMBER(SEARCH("S6",$AD14)),1,0) -> 0 | AP14: =IF(ISNUMBER(SEARCH("TR",$AD14)),1,0) -> 0
A15: ES-PAD-05 | B15: Cuenta básica | C15: Real Decreto-ley 19/2017 (cuentas de pago básicas) | D15: art. 4.2 | E15: ES_ley | F15: Vigente | G15: Abstenerse | H15: E0; E9 | I15: Expediente_completo | J15: Acceso_inclusion | K15: No especificado | L15: Interesado | M15: Cuenta_pago_basica | N15: Si | O15: El acceso a la cuenta de pago básica no podrá supeditarse a la adquisición de otros servicios, ni a la adquisición de participaciones en el capital | P15: https://www.boe.es/buscar/act.php?id=BOE-A-2017-13644 | Q15: Alta | R15: Salvo que lo imponga la normativa o sea requisito ineludible para toda la clientela. | S15: =IF(ISNUMBER(SEARCH("E0",$H15)),1,0) -> 1 | T15: =IF(ISNUMBER(SEARCH("E1",$H15)),1,0) -> 0 | U15: =IF(ISNUMBER(SEARCH("E2",$H15)),1,0) -> 0 | V15: =IF(ISNUMBER(SEARCH("E3",$H15)),1,0) -> 0 | W15: =IF(ISNUMBER(SEARCH("E4",$H15)),1,0) -> 0 | X15: =IF(ISNUMBER(SEARCH("E5",$H15)),1,0) -> 0 | Y15: =IF(ISNUMBER(SEARCH("E6",$H15)),1,0) -> 0 | Z15: =IF(ISNUMBER(SEARCH("E7",$H15)),1,0) -> 0 | AA15: =IF(ISNUMBER(SEARCH("E8",$H15)),1,0) -> 0 | AB15: =IF(ISNUMBER(SEARCH("E9",$H15)),1,0) -> 1 | AC15: =IF(ISNUMBER(SEARCH("TR",$H15)),1,0) -> 0 | AD15: S0; S6 | AE15: =IF(ISNUMBER(SEARCH("S0",$AD15)),1,0) -> 1 | AF15: =IF(ISNUMBER(SEARCH("R01",$AD15)),1,0) -> 0 | AG15: =IF(ISNUMBER(SEARCH("R02R03",$AD15)),1,0) -> 0 | AH15: =IF(ISNUMBER(SEARCH("R04",$AD15)),1,0) -> 0 | AI15: =IF(ISNUMBER(SEARCH("R05",$AD15)),1,0) -> 0 | AJ15: =IF(ISNUMBER(SEARCH("S3R06",$AD15)),1,0) -> 0 | AK15: =IF(ISNUMBER(SEARCH("R07",$AD15)),1,0) -> 0 | AL15: =IF(ISNUMBER(SEARCH("R09",$AD15)),1,0) -> 0 | AM15: =IF(ISNUMBER(SEARCH("R10",$AD15)),1,0) -> 0 | AN15: =IF(ISNUMBER(SEARCH("S5",$AD15)),1,0) -> 0 | AO15: =IF(ISNUMBER(SEARCH("S6",$AD15)),1,0) -> 1 | AP15: =IF(ISNUMBER(SEARCH("TR",$AD15)),1,0) -> 0
A16: ES-PAD-06 | B16: Cuenta básica | C16: Real Decreto-ley 19/2017 (cuentas de pago básicas) | D16: art. 5.1 | E16: ES_ley | F16: Vigente | G16: Informar_interesado | H16: E8 | I16: Motivo_decision | J16: Acceso_inclusion | K16: No especificado | L16: Interesado | M16: Cuenta_pago_basica | N16: Si | O16: La entidad de crédito deberá informar al potencial cliente de la denegación de la apertura de una cuenta de pago básica, a menos que no resulte compatible con lo establecido en la Ley 10/2010 | P16: https://www.boe.es/buscar/act.php?id=BOE-A-2017-13644 | Q16: Alta | R16: Excepción también por seguridad nacional u orden público. | S16: =IF(ISNUMBER(SEARCH("E0",$H16)),1,0) -> 0 | T16: =IF(ISNUMBER(SEARCH("E1",$H16)),1,0) -> 0 | U16: =IF(ISNUMBER(SEARCH("E2",$H16)),1,0) -> 0 | V16: =IF(ISNUMBER(SEARCH("E3",$H16)),1,0) -> 0 | W16: =IF(ISNUMBER(SEARCH("E4",$H16)),1,0) -> 0 | X16: =IF(ISNUMBER(SEARCH("E5",$H16)),1,0) -> 0 | Y16: =IF(ISNUMBER(SEARCH("E6",$H16)),1,0) -> 0 | Z16: =IF(ISNUMBER(SEARCH("E7",$H16)),1,0) -> 0 | AA16: =IF(ISNUMBER(SEARCH("E8",$H16)),1,0) -> 1 | AB16: =IF(ISNUMBER(SEARCH("E9",$H16)),1,0) -> 0 | AC16: =IF(ISNUMBER(SEARCH("TR",$H16)),1,0) -> 0 | AD16: S5 | AE16: =IF(ISNUMBER(SEARCH("S0",$AD16)),1,0) -> 0 | AF16: =IF(ISNUMBER(SEARCH("R01",$AD16)),1,0) -> 0 | AG16: =IF(ISNUMBER(SEARCH("R02R03",$AD16)),1,0) -> 0 | AH16: =IF(ISNUMBER(SEARCH("R04",$AD16)),1,0) -> 0 | AI16: =IF(ISNUMBER(SEARCH("R05",$AD16)),1,0) -> 0 | AJ16: =IF(ISNUMBER(SEARCH("S3R06",$AD16)),1,0) -> 0 | AK16: =IF(ISNUMBER(SEARCH("R07",$AD16)),1,0) -> 0 | AL16: =IF(ISNUMBER(SEARCH("R09",$AD16)),1,0) -> 0 | AM16: =IF(ISNUMBER(SEARCH("R10",$AD16)),1,0) -> 0 | AN16: =IF(ISNUMBER(SEARCH("S5",$AD16)),1,0) -> 1 | AO16: =IF(ISNUMBER(SEARCH("S6",$AD16)),1,0) -> 0 | AP16: =IF(ISNUMBER(SEARCH("TR",$AD16)),1,0) -> 0
A17: ES-PAD-07 | B17: Cuenta básica | C17: Real Decreto-ley 19/2017 (cuentas de pago básicas) | D17: art. 5.2 | E17: ES_ley | F17: Vigente | G17: Motivar | H17: E8 | I17: Motivo_decision | J17: Transparencia_consumidor | K17: 10 días hábiles desde la recepción de la solicitud completa | L17: Interesado | M17: Cuenta_pago_basica | N17: Si | O17: La denegación se notificará al potencial cliente por escrito y de manera gratuita, expresando las razones concretas en las que se funda [...] a más tardar en un plazo máximo de diez días hábiles | P17: https://www.boe.es/buscar/act.php?id=BOE-A-2017-13644 | Q17: Alta | S17: =IF(ISNUMBER(SEARCH("E0",$H17)),1,0) -> 0 | T17: =IF(ISNUMBER(SEARCH("E1",$H17)),1,0) -> 0 | U17: =IF(ISNUMBER(SEARCH("E2",$H17)),1,0) -> 0 | V17: =IF(ISNUMBER(SEARCH("E3",$H17)),1,0) -> 0 | W17: =IF(ISNUMBER(SEARCH("E4",$H17)),1,0) -> 0 | X17: =IF(ISNUMBER(SEARCH("E5",$H17)),1,0) -> 0 | Y17: =IF(ISNUMBER(SEARCH("E6",$H17)),1,0) -> 0 | Z17: =IF(ISNUMBER(SEARCH("E7",$H17)),1,0) -> 0 | AA17: =IF(ISNUMBER(SEARCH("E8",$H17)),1,0) -> 1 | AB17: =IF(ISNUMBER(SEARCH("E9",$H17)),1,0) -> 0 | AC17: =IF(ISNUMBER(SEARCH("TR",$H17)),1,0) -> 0 | AD17: S5 | AE17: =IF(ISNUMBER(SEARCH("S0",$AD17)),1,0) -> 0 | AF17: =IF(ISNUMBER(SEARCH("R01",$AD17)),1,0) -> 0 | AG17: =IF(ISNUMBER(SEARCH("R02R03",$AD17)),1,0) -> 0 | AH17: =IF(ISNUMBER(SEARCH("R04",$AD17)),1,0) -> 0 | AI17: =IF(ISNUMBER(SEARCH("R05",$AD17)),1,0) -> 0 | AJ17: =IF(ISNUMBER(SEARCH("S3R06",$AD17)),1,0) -> 0 | AK17: =IF(ISNUMBER(SEARCH("R07",$AD17)),1,0) -> 0 | AL17: =IF(ISNUMBER(SEARCH("R09",$AD17)),1,0) -> 0 | AM17: =IF(ISNUMBER(SEARCH("R10",$AD17)),1,0) -> 0 | AN17: =IF(ISNUMBER(SEARCH("S5",$AD17)),1,0) -> 1 | AO17: =IF(ISNUMBER(SEARCH("S6",$AD17)),1,0) -> 0 | AP17: =IF(ISNUMBER(SEARCH("TR",$AD17)),1,0) -> 0
A18: ES-PAD-08 | B18: Cuenta básica | C18: Real Decreto-ley 19/2017 (cuentas de pago básicas) | D18: art. 5.3 | E18: ES_ley | F18: Vigente | G18: Informar_interesado | H18: E8 | I18: Motivo_decision | J18: Reclamaciones | K18: Al notificar la denegación | L18: Interesado | M18: Cuenta_pago_basica | N18: Si | O18: al notificar el rechazo de la solicitud de apertura, las entidades informarán al potencial cliente del procedimiento que ha de seguir para presentar una reclamación contra la denegación | P18: https://www.boe.es/buscar/act.php?id=BOE-A-2017-13644 | Q18: Alta | R18: Y de su derecho al procedimiento del art. 30 Ley 44/2002 (Banco de España). Véase también art. 6 Orden ECE/228/2019 (la negativa a abrir es reclamable conforme a la DA 1.ª Ley 7/2017). | S18: =IF(ISNUMBER(SEARCH("E0",$H18)),1,0) -> 0 | T18: =IF(ISNUMBER(SEARCH("E1",$H18)),1,0) -> 0 | U18: =IF(ISNUMBER(SEARCH("E2",$H18)),1,0) -> 0 | V18: =IF(ISNUMBER(SEARCH("E3",$H18)),1,0) -> 0 | W18: =IF(ISNUMBER(SEARCH("E4",$H18)),1,0) -> 0 | X18: =IF(ISNUMBER(SEARCH("E5",$H18)),1,0) -> 0 | Y18: =IF(ISNUMBER(SEARCH("E6",$H18)),1,0) -> 0 | Z18: =IF(ISNUMBER(SEARCH("E7",$H18)),1,0) -> 0 | AA18: =IF(ISNUMBER(SEARCH("E8",$H18)),1,0) -> 1 | AB18: =IF(ISNUMBER(SEARCH("E9",$H18)),1,0) -> 0 | AC18: =IF(ISNUMBER(SEARCH("TR",$H18)),1,0) -> 0 | AD18: S5 | AE18: =IF(ISNUMBER(SEARCH("S0",$AD18)),1,0) -> 0 | AF18: =IF(ISNUMBER(SEARCH("R01",$AD18)),1,0) -> 0 | AG18: =IF(ISNUMBER(SEARCH("R02R03",$AD18)),1,0) -> 0 | AH18: =IF(ISNUMBER(SEARCH("R04",$AD18)),1,0) -> 0 | AI18: =IF(ISNUMBER(SEARCH("R05",$AD18)),1,0) -> 0 | AJ18: =IF(ISNUMBER(SEARCH("S3R06",$AD18)),1,0) -> 0 | AK18: =IF(ISNUMBER(SEARCH("R07",$AD18)),1,0) -> 0 | AL18: =IF(ISNUMBER(SEARCH("R09",$AD18)),1,0) -> 0 | AM18: =IF(ISNUMBER(SEARCH("R10",$AD18)),1,0) -> 0 | AN18: =IF(ISNUMBER(SEARCH("S5",$AD18)),1,0) -> 1 | AO18: =IF(ISNUMBER(SEARCH("S6",$AD18)),1,0) -> 0 | AP18: =IF(ISNUMBER(SEARCH("TR",$AD18)),1,0) -> 0
A19: ES-PAD-09 | B19: Cuenta básica | C19: Real Decreto-ley 19/2017 (cuentas de pago básicas) | D19: art. 10.2 | E19: ES_ley | F19: Vigente | G19: Informar_interesado | H19: TR | I19: Informacion_tratamiento | J19: Transparencia_consumidor | K19: No especificado | L19: Interesado | M19: Cuenta_pago_basica | N19: Parcial | O19: se indicará claramente en la publicidad e información facilitada por las entidades de crédito que para tener acceso a una cuenta de pago básica no es obligatorio adquirir otros servicios | P19: https://www.boe.es/buscar/act.php?id=BOE-A-2017-13644 | Q19: Alta | R19: Incluye uso destacado de la denominación «cuenta de pago básica». Información sobre el producto (no hay categoría de dato específica). | S19: =IF(ISNUMBER(SEARCH("E0",$H19)),1,0) -> 0 | T19: =IF(ISNUMBER(SEARCH("E1",$H19)),1,0) -> 0 | U19: =IF(ISNUMBER(SEARCH("E2",$H19)),1,0) -> 0 | V19: =IF(ISNUMBER(SEARCH("E3",$H19)),1,0) -> 0 | W19: =IF(ISNUMBER(SEARCH("E4",$H19)),1,0) -> 0 | X19: =IF(ISNUMBER(SEARCH("E5",$H19)),1,0) -> 0 | Y19: =IF(ISNUMBER(SEARCH("E6",$H19)),1,0) -> 0 | Z19: =IF(ISNUMBER(SEARCH("E7",$H19)),1,0) -> 0 | AA19: =IF(ISNUMBER(SEARCH("E8",$H19)),1,0) -> 0 | AB19: =IF(ISNUMBER(SEARCH("E9",$H19)),1,0) -> 0 | AC19: =IF(ISNUMBER(SEARCH("TR",$H19)),1,0) -> 1 | AD19: TR | AE19: =IF(ISNUMBER(SEARCH("S0",$AD19)),1,0) -> 0 | AF19: =IF(ISNUMBER(SEARCH("R01",$AD19)),1,0) -> 0 | AG19: =IF(ISNUMBER(SEARCH("R02R03",$AD19)),1,0) -> 0 | AH19: =IF(ISNUMBER(SEARCH("R04",$AD19)),1,0) -> 0 | AI19: =IF(ISNUMBER(SEARCH("R05",$AD19)),1,0) -> 0 | AJ19: =IF(ISNUMBER(SEARCH("S3R06",$AD19)),1,0) -> 0 | AK19: =IF(ISNUMBER(SEARCH("R07",$AD19)),1,0) -> 0 | AL19: =IF(ISNUMBER(SEARCH("R09",$AD19)),1,0) -> 0 | AM19: =IF(ISNUMBER(SEARCH("R10",$AD19)),1,0) -> 0 | AN19: =IF(ISNUMBER(SEARCH("S5",$AD19)),1,0) -> 0 | AO19: =IF(ISNUMBER(SEARCH("S6",$AD19)),1,0) -> 0 | AP19: =IF(ISNUMBER(SEARCH("TR",$AD19)),1,0) -> 1
A20: ES-PAD-10 | B20: Cuenta básica | C20: Real Decreto-ley 19/2017 (cuentas de pago básicas) | D20: art. 10.3 | E20: ES_ley | F20: Vigente | G20: Informar_interesado | H20: TR | I20: Informacion_tratamiento | J20: Transparencia_consumidor | K20: No especificado | L20: Interesado | M20: Cuenta_pago_basica | N20: Si | O20: las entidades de crédito deberán tener a disposición de los clientes o potenciales clientes gratuitamente en todos sus canales de distribución al consumidor, información y asistencia | P20: https://www.boe.es/buscar/act.php?id=BOE-A-2017-13644 | Q20: Alta | R20: Sobre servicios incluidos, comisiones y condiciones de uso. Información sobre el producto. | S20: =IF(ISNUMBER(SEARCH("E0",$H20)),1,0) -> 0 | T20: =IF(ISNUMBER(SEARCH("E1",$H20)),1,0) -> 0 | U20: =IF(ISNUMBER(SEARCH("E2",$H20)),1,0) -> 0 | V20: =IF(ISNUMBER(SEARCH("E3",$H20)),1,0) -> 0 | W20: =IF(ISNUMBER(SEARCH("E4",$H20)),1,0) -> 0 | X20: =IF(ISNUMBER(SEARCH("E5",$H20)),1,0) -> 0 | Y20: =IF(ISNUMBER(SEARCH("E6",$H20)),1,0) -> 0 | Z20: =IF(ISNUMBER(SEARCH("E7",$H20)),1,0) -> 0 | AA20: =IF(ISNUMBER(SEARCH("E8",$H20)),1,0) -> 0 | AB20: =IF(ISNUMBER(SEARCH("E9",$H20)),1,0) -> 0 | AC20: =IF(ISNUMBER(SEARCH("TR",$H20)),1,0) -> 1 | AD20: TR | AE20: =IF(ISNUMBER(SEARCH("S0",$AD20)),1,0) -> 0 | AF20: =IF(ISNUMBER(SEARCH("R01",$AD20)),1,0) -> 0 | AG20: =IF(ISNUMBER(SEARCH("R02R03",$AD20)),1,0) -> 0 | AH20: =IF(ISNUMBER(SEARCH("R04",$AD20)),1,0) -> 0 | AI20: =IF(ISNUMBER(SEARCH("R05",$AD20)),1,0) -> 0 | AJ20: =IF(ISNUMBER(SEARCH("S3R06",$AD20)),1,0) -> 0 | AK20: =IF(ISNUMBER(SEARCH("R07",$AD20)),1,0) -> 0 | AL20: =IF(ISNUMBER(SEARCH("R09",$AD20)),1,0) -> 0 | AM20: =IF(ISNUMBER(SEARCH("R10",$AD20)),1,0) -> 0 | AN20: =IF(ISNUMBER(SEARCH("S5",$AD20)),1,0) -> 0 | AO20: =IF(ISNUMBER(SEARCH("S6",$AD20)),1,0) -> 0 | AP20: =IF(ISNUMBER(SEARCH("TR",$AD20)),1,0) -> 1
A21: ES-PAD-11 | B21: Cuenta básica | C21: Orden ECE/228/2019 (cuentas de pago básicas) | D21: art. 8.1.e) | E21: ES_reglamento | F21: Vigente | G21: Informar_interesado | H21: TR | I21: Informacion_tratamiento | J21: Acceso_inclusion | K21: No especificado | L21: Interesado | M21: Cuenta_pago_basica | N21: Si | O21: el procedimiento a seguir para la apertura de una cuenta de pago básica, incluyendo, en particular, la información y documentación a presentar | P21: https://www.boe.es/buscar/act.php?id=BOE-A-2019-3113 | Q21: Alta | R21: Norma añadida (no listada en el encargo) por desarrollar el art. 10 RDL 19/2017. El art. 8.1 obliga además a aprobar, ejecutar y evaluar el impacto de procedimientos de difusión; el 8.2, medidas para consumidores vulnerables. | S21: =IF(ISNUMBER(SEARCH("E0",$H21)),1,0) -> 0 | T21: =IF(ISNUMBER(SEARCH("E1",$H21)),1,0) -> 0 | U21: =IF(ISNUMBER(SEARCH("E2",$H21)),1,0) -> 0 | V21: =IF(ISNUMBER(SEARCH("E3",$H21)),1,0) -> 0 | W21: =IF(ISNUMBER(SEARCH("E4",$H21)),1,0) -> 0 | X21: =IF(ISNUMBER(SEARCH("E5",$H21)),1,0) -> 0 | Y21: =IF(ISNUMBER(SEARCH("E6",$H21)),1,0) -> 0 | Z21: =IF(ISNUMBER(SEARCH("E7",$H21)),1,0) -> 0 | AA21: =IF(ISNUMBER(SEARCH("E8",$H21)),1,0) -> 0 | AB21: =IF(ISNUMBER(SEARCH("E9",$H21)),1,0) -> 0 | AC21: =IF(ISNUMBER(SEARCH("TR",$H21)),1,0) -> 1 | AD21: TR | AE21: =IF(ISNUMBER(SEARCH("S0",$AD21)),1,0) -> 0 | AF21: =IF(ISNUMBER(SEARCH("R01",$AD21)),1,0) -> 0 | AG21: =IF(ISNUMBER(SEARCH("R02R03",$AD21)),1,0) -> 0 | AH21: =IF(ISNUMBER(SEARCH("R04",$AD21)),1,0) -> 0 | AI21: =IF(ISNUMBER(SEARCH("R05",$AD21)),1,0) -> 0 | AJ21: =IF(ISNUMBER(SEARCH("S3R06",$AD21)),1,0) -> 0 | AK21: =IF(ISNUMBER(SEARCH("R07",$AD21)),1,0) -> 0 | AL21: =IF(ISNUMBER(SEARCH("R09",$AD21)),1,0) -> 0 | AM21: =IF(ISNUMBER(SEARCH("R10",$AD21)),1,0) -> 0 | AN21: =IF(ISNUMBER(SEARCH("S5",$AD21)),1,0) -> 0 | AO21: =IF(ISNUMBER(SEARCH("S6",$AD21)),1,0) -> 0 | AP21: =IF(ISNUMBER(SEARCH("TR",$AD21)),1,0) -> 1
A22: ES-PAD-12 | B22: Cuenta básica | C22: Real Decreto 164/2019 (gratuidad CPB vulnerables) | D22: art. 4.4 | E22: ES_reglamento | F22: Vigente | G22: Informar_interesado | H22: E8; E9 | I22: Motivo_decision | J22: Acceso_inclusion | K22: Máximo 30 días desde la aportación completa | L22: Interesado | M22: Cuenta_pago_basica | N22: Si | O22: El reconocimiento o la denegación de la condición de gratuidad se comunicará al cliente, por escrito y de manera gratuita, en el plazo máximo de treinta días desde la fecha de la aportación completa | P22: https://www.boe.es/buscar/act.php?id=BOE-A-2019-4906 | Q22: Alta | R22: Silencio positivo: transcurrido el plazo sin comunicación se entiende reconocida la gratuidad. No exige expresamente motivar. Puede solicitarse en el alta o después (art. 2.2). | S22: =IF(ISNUMBER(SEARCH("E0",$H22)),1,0) -> 0 | T22: =IF(ISNUMBER(SEARCH("E1",$H22)),1,0) -> 0 | U22: =IF(ISNUMBER(SEARCH("E2",$H22)),1,0) -> 0 | V22: =IF(ISNUMBER(SEARCH("E3",$H22)),1,0) -> 0 | W22: =IF(ISNUMBER(SEARCH("E4",$H22)),1,0) -> 0 | X22: =IF(ISNUMBER(SEARCH("E5",$H22)),1,0) -> 0 | Y22: =IF(ISNUMBER(SEARCH("E6",$H22)),1,0) -> 0 | Z22: =IF(ISNUMBER(SEARCH("E7",$H22)),1,0) -> 0 | AA22: =IF(ISNUMBER(SEARCH("E8",$H22)),1,0) -> 1 | AB22: =IF(ISNUMBER(SEARCH("E9",$H22)),1,0) -> 1 | AC22: =IF(ISNUMBER(SEARCH("TR",$H22)),1,0) -> 0 | AD22: S5; S6 | AE22: =IF(ISNUMBER(SEARCH("S0",$AD22)),1,0) -> 0 | AF22: =IF(ISNUMBER(SEARCH("R01",$AD22)),1,0) -> 0 | AG22: =IF(ISNUMBER(SEARCH("R02R03",$AD22)),1,0) -> 0 | AH22: =IF(ISNUMBER(SEARCH("R04",$AD22)),1,0) -> 0 | AI22: =IF(ISNUMBER(SEARCH("R05",$AD22)),1,0) -> 0 | AJ22: =IF(ISNUMBER(SEARCH("S3R06",$AD22)),1,0) -> 0 | AK22: =IF(ISNUMBER(SEARCH("R07",$AD22)),1,0) -> 0 | AL22: =IF(ISNUMBER(SEARCH("R09",$AD22)),1,0) -> 0 | AM22: =IF(ISNUMBER(SEARCH("R10",$AD22)),1,0) -> 0 | AN22: =IF(ISNUMBER(SEARCH("S5",$AD22)),1,0) -> 1 | AO22: =IF(ISNUMBER(SEARCH("S6",$AD22)),1,0) -> 1 | AP22: =IF(ISNUMBER(SEARCH("TR",$AD22)),1,0) -> 0
A23: ES-PAD-13 | B23: Cuenta básica | C23: Real Decreto 164/2019 (gratuidad CPB vulnerables) | D23: art. 4.4 (párrafo 2) | E23: ES_reglamento | F23: Vigente | G23: Informar_interesado | H23: E8 | I23: Motivo_decision | J23: Reclamaciones | K23: Con la comunicación de la denegación | L23: Interesado | M23: Cuenta_pago_basica | N23: Si | O23: El escrito incluirá la información del derecho del cliente a presentar una reclamación contra la denegación, conforme a lo previsto en la disposición adicional segunda. | P23: https://www.boe.es/buscar/act.php?id=BOE-A-2019-4906 | Q23: Alta | S23: =IF(ISNUMBER(SEARCH("E0",$H23)),1,0) -> 0 | T23: =IF(ISNUMBER(SEARCH("E1",$H23)),1,0) -> 0 | U23: =IF(ISNUMBER(SEARCH("E2",$H23)),1,0) -> 0 | V23: =IF(ISNUMBER(SEARCH("E3",$H23)),1,0) -> 0 | W23: =IF(ISNUMBER(SEARCH("E4",$H23)),1,0) -> 0 | X23: =IF(ISNUMBER(SEARCH("E5",$H23)),1,0) -> 0 | Y23: =IF(ISNUMBER(SEARCH("E6",$H23)),1,0) -> 0 | Z23: =IF(ISNUMBER(SEARCH("E7",$H23)),1,0) -> 0 | AA23: =IF(ISNUMBER(SEARCH("E8",$H23)),1,0) -> 1 | AB23: =IF(ISNUMBER(SEARCH("E9",$H23)),1,0) -> 0 | AC23: =IF(ISNUMBER(SEARCH("TR",$H23)),1,0) -> 0 | AD23: S5 | AE23: =IF(ISNUMBER(SEARCH("S0",$AD23)),1,0) -> 0 | AF23: =IF(ISNUMBER(SEARCH("R01",$AD23)),1,0) -> 0 | AG23: =IF(ISNUMBER(SEARCH("R02R03",$AD23)),1,0) -> 0 | AH23: =IF(ISNUMBER(SEARCH("R04",$AD23)),1,0) -> 0 | AI23: =IF(ISNUMBER(SEARCH("R05",$AD23)),1,0) -> 0 | AJ23: =IF(ISNUMBER(SEARCH("S3R06",$AD23)),1,0) -> 0 | AK23: =IF(ISNUMBER(SEARCH("R07",$AD23)),1,0) -> 0 | AL23: =IF(ISNUMBER(SEARCH("R09",$AD23)),1,0) -> 0 | AM23: =IF(ISNUMBER(SEARCH("R10",$AD23)),1,0) -> 0 | AN23: =IF(ISNUMBER(SEARCH("S5",$AD23)),1,0) -> 1 | AO23: =IF(ISNUMBER(SEARCH("S6",$AD23)),1,0) -> 0 | AP23: =IF(ISNUMBER(SEARCH("TR",$AD23)),1,0) -> 0
A24: ES-PAD-14 | B24: Cuenta básica | C24: Real Decreto 164/2019 (gratuidad CPB vulnerables) | D24: art. 5 | E24: ES_reglamento | F24: Vigente | G24: Informar_interesado | H24: E9; TR | I24: Informacion_tratamiento | J24: Acceso_inclusion | K24: En el momento de la contratación | L24: Interesado | M24: Cuenta_pago_basica | N24: Parcial | O24: informará a los clientes sobre dichas condiciones en el momento de la contratación de la cuenta de pago básica | P24: https://www.boe.es/buscar/act.php?id=BOE-A-2019-4906 | Q24: Alta | R24: Además, incluir las condiciones de gratuidad en la información general del art. 10 RDL 19/2017 y art. 8 Orden ECE/228/2019 (TR). | S24: =IF(ISNUMBER(SEARCH("E0",$H24)),1,0) -> 0 | T24: =IF(ISNUMBER(SEARCH("E1",$H24)),1,0) -> 0 | U24: =IF(ISNUMBER(SEARCH("E2",$H24)),1,0) -> 0 | V24: =IF(ISNUMBER(SEARCH("E3",$H24)),1,0) -> 0 | W24: =IF(ISNUMBER(SEARCH("E4",$H24)),1,0) -> 0 | X24: =IF(ISNUMBER(SEARCH("E5",$H24)),1,0) -> 0 | Y24: =IF(ISNUMBER(SEARCH("E6",$H24)),1,0) -> 0 | Z24: =IF(ISNUMBER(SEARCH("E7",$H24)),1,0) -> 0 | AA24: =IF(ISNUMBER(SEARCH("E8",$H24)),1,0) -> 0 | AB24: =IF(ISNUMBER(SEARCH("E9",$H24)),1,0) -> 1 | AC24: =IF(ISNUMBER(SEARCH("TR",$H24)),1,0) -> 1 | AD24: S6; TR | AE24: =IF(ISNUMBER(SEARCH("S0",$AD24)),1,0) -> 0 | AF24: =IF(ISNUMBER(SEARCH("R01",$AD24)),1,0) -> 0 | AG24: =IF(ISNUMBER(SEARCH("R02R03",$AD24)),1,0) -> 0 | AH24: =IF(ISNUMBER(SEARCH("R04",$AD24)),1,0) -> 0 | AI24: =IF(ISNUMBER(SEARCH("R05",$AD24)),1,0) -> 0 | AJ24: =IF(ISNUMBER(SEARCH("S3R06",$AD24)),1,0) -> 0 | AK24: =IF(ISNUMBER(SEARCH("R07",$AD24)),1,0) -> 0 | AL24: =IF(ISNUMBER(SEARCH("R09",$AD24)),1,0) -> 0 | AM24: =IF(ISNUMBER(SEARCH("R10",$AD24)),1,0) -> 0 | AN24: =IF(ISNUMBER(SEARCH("S5",$AD24)),1,0) -> 0 | AO24: =IF(ISNUMBER(SEARCH("S6",$AD24)),1,0) -> 1 | AP24: =IF(ISNUMBER(SEARCH("TR",$AD24)),1,0) -> 1
A25: ES-PAD-15 | B25: Cuenta básica | C25: Real Decreto 164/2019 (gratuidad CPB vulnerables) | D25: art. 7.1 | E25: ES_reglamento | F25: Vigente | G25: Conservar | H25: E8; E9 | I25: Expediente_completo | J25: Acceso_inclusion | K25: Mínimo 6 años | L25: Uso_interno | M25: Cuenta_pago_basica | N25: Si | O25: conservarán [...] durante un plazo mínimo de 6 años, la documentación señalada en los artículos 4, 5 y 6, con independencia de si la condición de gratuidad de la cuenta se ha reconocido o no | P25: https://www.boe.es/buscar/act.php?id=BOE-A-2019-4906 | Q25: Alta | R25: Art. 7.2: el cómputo se inicia desde la denegación o desde el fin de la gratuidad. Finalidad declarada: verificar el cumplimiento. | S25: =IF(ISNUMBER(SEARCH("E0",$H25)),1,0) -> 0 | T25: =IF(ISNUMBER(SEARCH("E1",$H25)),1,0) -> 0 | U25: =IF(ISNUMBER(SEARCH("E2",$H25)),1,0) -> 0 | V25: =IF(ISNUMBER(SEARCH("E3",$H25)),1,0) -> 0 | W25: =IF(ISNUMBER(SEARCH("E4",$H25)),1,0) -> 0 | X25: =IF(ISNUMBER(SEARCH("E5",$H25)),1,0) -> 0 | Y25: =IF(ISNUMBER(SEARCH("E6",$H25)),1,0) -> 0 | Z25: =IF(ISNUMBER(SEARCH("E7",$H25)),1,0) -> 0 | AA25: =IF(ISNUMBER(SEARCH("E8",$H25)),1,0) -> 1 | AB25: =IF(ISNUMBER(SEARCH("E9",$H25)),1,0) -> 1 | AC25: =IF(ISNUMBER(SEARCH("TR",$H25)),1,0) -> 0 | AD25: S5; S6 | AE25: =IF(ISNUMBER(SEARCH("S0",$AD25)),1,0) -> 0 | AF25: =IF(ISNUMBER(SEARCH("R01",$AD25)),1,0) -> 0 | AG25: =IF(ISNUMBER(SEARCH("R02R03",$AD25)),1,0) -> 0 | AH25: =IF(ISNUMBER(SEARCH("R04",$AD25)),1,0) -> 0 | AI25: =IF(ISNUMBER(SEARCH("R05",$AD25)),1,0) -> 0 | AJ25: =IF(ISNUMBER(SEARCH("S3R06",$AD25)),1,0) -> 0 | AK25: =IF(ISNUMBER(SEARCH("R07",$AD25)),1,0) -> 0 | AL25: =IF(ISNUMBER(SEARCH("R09",$AD25)),1,0) -> 0 | AM25: =IF(ISNUMBER(SEARCH("R10",$AD25)),1,0) -> 0 | AN25: =IF(ISNUMBER(SEARCH("S5",$AD25)),1,0) -> 1 | AO25: =IF(ISNUMBER(SEARCH("S6",$AD25)),1,0) -> 1 | AP25: =IF(ISNUMBER(SEARCH("TR",$AD25)),1,0) -> 0
A26: ES-TR-01 | B26: Atención al cliente ES | C26: Orden ECO/734/2004 (servicios de atención al cliente) | D26: art. 3 | E26: ES_reglamento | F26: Vigente | G26: Informar_interesado | H26: E8 | I26: Motivo_decision | J26: Reclamaciones | K26: No especificado | L26: Interesado | M26: Todas_entidades_obligadas | N26: Parcial | O26: las entidades [...] estarán obligadas a atender y resolver las quejas y reclamaciones que sus clientes les presenten, relacionadas con sus intereses y derechos legalmente reconocidos | P26: https://www.boe.es/buscar/act.php?id=BOE-A-2004-5290 | Q26: Alta | R26: Aplica a reclamaciones contra la denegación del alta (vía SAC). Orden parcialmente derogada por la Ley 10/2025, de 26 de diciembre (arts. 6 y 9 a 16, incluidos deberes de información, plazos y procedimiento); revisar Ley 10/2025. 'Clientes': alcance sobre potenciales clientes dudoso. | S26: =IF(ISNUMBER(SEARCH("E0",$H26)),1,0) -> 0 | T26: =IF(ISNUMBER(SEARCH("E1",$H26)),1,0) -> 0 | U26: =IF(ISNUMBER(SEARCH("E2",$H26)),1,0) -> 0 | V26: =IF(ISNUMBER(SEARCH("E3",$H26)),1,0) -> 0 | W26: =IF(ISNUMBER(SEARCH("E4",$H26)),1,0) -> 0 | X26: =IF(ISNUMBER(SEARCH("E5",$H26)),1,0) -> 0 | Y26: =IF(ISNUMBER(SEARCH("E6",$H26)),1,0) -> 0 | Z26: =IF(ISNUMBER(SEARCH("E7",$H26)),1,0) -> 0 | AA26: =IF(ISNUMBER(SEARCH("E8",$H26)),1,0) -> 1 | AB26: =IF(ISNUMBER(SEARCH("E9",$H26)),1,0) -> 0 | AC26: =IF(ISNUMBER(SEARCH("TR",$H26)),1,0) -> 0 | AD26: S5 | AE26: =IF(ISNUMBER(SEARCH("S0",$AD26)),1,0) -> 0 | AF26: =IF(ISNUMBER(SEARCH("R01",$AD26)),1,0) -> 0 | AG26: =IF(ISNUMBER(SEARCH("R02R03",$AD26)),1,0) -> 0 | AH26: =IF(ISNUMBER(SEARCH("R04",$AD26)),1,0) -> 0 | AI26: =IF(ISNUMBER(SEARCH("R05",$AD26)),1,0) -> 0 | AJ26: =IF(ISNUMBER(SEARCH("S3R06",$AD26)),1,0) -> 0 | AK26: =IF(ISNUMBER(SEARCH("R07",$AD26)),1,0) -> 0 | AL26: =IF(ISNUMBER(SEARCH("R09",$AD26)),1,0) -> 0 | AM26: =IF(ISNUMBER(SEARCH("R10",$AD26)),1,0) -> 0 | AN26: =IF(ISNUMBER(SEARCH("S5",$AD26)),1,0) -> 1 | AO26: =IF(ISNUMBER(SEARCH("S6",$AD26)),1,0) -> 0 | AP26: =IF(ISNUMBER(SEARCH("TR",$AD26)),1,0) -> 0
A27: ES-TR-02 | B27: Atención al cliente ES | C27: Orden ECO/734/2004 (servicios de atención al cliente) | D27: art. 17.1 | E27: ES_reglamento | F27: Vigente | G27: Registrar | H27: E8 | I27: Motivo_decision | J27: Reclamaciones | K27: Anual (primer trimestre) | L27: Uso_interno | M27: Todas_entidades_obligadas | N27: Parcial | O27: un informe explicativo del desarrollo de su función durante el ejercicio precedente, que habrá de tener el contenido mínimo siguiente: a) resumen estadístico de las quejas y reclamaciones atendidas | P27: https://www.boe.es/buscar/act.php?id=BOE-A-2004-5290 | Q27: Alta | R27: Informe anual del SAC al consejo; solo alcanza al alta en cuanto haya reclamaciones por denegación. Pertinencia marginal. | S27: =IF(ISNUMBER(SEARCH("E0",$H27)),1,0) -> 0 | T27: =IF(ISNUMBER(SEARCH("E1",$H27)),1,0) -> 0 | U27: =IF(ISNUMBER(SEARCH("E2",$H27)),1,0) -> 0 | V27: =IF(ISNUMBER(SEARCH("E3",$H27)),1,0) -> 0 | W27: =IF(ISNUMBER(SEARCH("E4",$H27)),1,0) -> 0 | X27: =IF(ISNUMBER(SEARCH("E5",$H27)),1,0) -> 0 | Y27: =IF(ISNUMBER(SEARCH("E6",$H27)),1,0) -> 0 | Z27: =IF(ISNUMBER(SEARCH("E7",$H27)),1,0) -> 0 | AA27: =IF(ISNUMBER(SEARCH("E8",$H27)),1,0) -> 1 | AB27: =IF(ISNUMBER(SEARCH("E9",$H27)),1,0) -> 0 | AC27: =IF(ISNUMBER(SEARCH("TR",$H27)),1,0) -> 0 | AD27: S5 | AE27: =IF(ISNUMBER(SEARCH("S0",$AD27)),1,0) -> 0 | AF27: =IF(ISNUMBER(SEARCH("R01",$AD27)),1,0) -> 0 | AG27: =IF(ISNUMBER(SEARCH("R02R03",$AD27)),1,0) -> 0 | AH27: =IF(ISNUMBER(SEARCH("R04",$AD27)),1,0) -> 0 | AI27: =IF(ISNUMBER(SEARCH("R05",$AD27)),1,0) -> 0 | AJ27: =IF(ISNUMBER(SEARCH("S3R06",$AD27)),1,0) -> 0 | AK27: =IF(ISNUMBER(SEARCH("R07",$AD27)),1,0) -> 0 | AL27: =IF(ISNUMBER(SEARCH("R09",$AD27)),1,0) -> 0 | AM27: =IF(ISNUMBER(SEARCH("R10",$AD27)),1,0) -> 0 | AN27: =IF(ISNUMBER(SEARCH("S5",$AD27)),1,0) -> 1 | AO27: =IF(ISNUMBER(SEARCH("S6",$AD27)),1,0) -> 0 | AP27: =IF(ISNUMBER(SEARCH("TR",$AD27)),1,0) -> 0
A28: ES-TR-03 | B28: Atención al cliente ES | C28: Orden EHA/2899/2011 (transparencia bancaria) | D28: art. 6 | E28: ES_reglamento | F28: Vigente | G28: Informar_interesado | H28: E0 | I28: Informacion_tratamiento | J28: Transparencia_consumidor | K28: Con la debida antelación y antes de quedar vinculado | L28: Interesado | M28: Todas_entidades_obligadas | N28: Si | O28: Las entidades de crédito deberán facilitar de forma gratuita al cliente de servicios bancarios toda la información precontractual que sea legalmente exigible para adoptar una decisión informada | P28: https://www.boe.es/buscar/act.php?id=BOE-A-2011-16804 | Q28: Alta | R28: Duda de ámbito: para servicios/cuentas de pago el art. 34 remite a su normativa específica (Orden ECE/1263/2019); aplicable sin duda a depósitos a la vista. Información sobre el producto. | S28: =IF(ISNUMBER(SEARCH("E0",$H28)),1,0) -> 1 | T28: =IF(ISNUMBER(SEARCH("E1",$H28)),1,0) -> 0 | U28: =IF(ISNUMBER(SEARCH("E2",$H28)),1,0) -> 0 | V28: =IF(ISNUMBER(SEARCH("E3",$H28)),1,0) -> 0 | W28: =IF(ISNUMBER(SEARCH("E4",$H28)),1,0) -> 0 | X28: =IF(ISNUMBER(SEARCH("E5",$H28)),1,0) -> 0 | Y28: =IF(ISNUMBER(SEARCH("E6",$H28)),1,0) -> 0 | Z28: =IF(ISNUMBER(SEARCH("E7",$H28)),1,0) -> 0 | AA28: =IF(ISNUMBER(SEARCH("E8",$H28)),1,0) -> 0 | AB28: =IF(ISNUMBER(SEARCH("E9",$H28)),1,0) -> 0 | AC28: =IF(ISNUMBER(SEARCH("TR",$H28)),1,0) -> 0 | AD28: S0 | AE28: =IF(ISNUMBER(SEARCH("S0",$AD28)),1,0) -> 1 | AF28: =IF(ISNUMBER(SEARCH("R01",$AD28)),1,0) -> 0 | AG28: =IF(ISNUMBER(SEARCH("R02R03",$AD28)),1,0) -> 0 | AH28: =IF(ISNUMBER(SEARCH("R04",$AD28)),1,0) -> 0 | AI28: =IF(ISNUMBER(SEARCH("R05",$AD28)),1,0) -> 0 | AJ28: =IF(ISNUMBER(SEARCH("S3R06",$AD28)),1,0) -> 0 | AK28: =IF(ISNUMBER(SEARCH("R07",$AD28)),1,0) -> 0 | AL28: =IF(ISNUMBER(SEARCH("R09",$AD28)),1,0) -> 0 | AM28: =IF(ISNUMBER(SEARCH("R10",$AD28)),1,0) -> 0 | AN28: =IF(ISNUMBER(SEARCH("S5",$AD28)),1,0) -> 0 | AO28: =IF(ISNUMBER(SEARCH("S6",$AD28)),1,0) -> 0 | AP28: =IF(ISNUMBER(SEARCH("TR",$AD28)),1,0) -> 0
